<?xml version="1.0" ?>
<!-- =================================================================================== -->
<!-- |    This document was autogenerated by xacro from /home/omron/Omron_AMR_ROS2/src/amr_visualisation/urdf/AMR_Platform.urdf.xacro | -->
<!-- |    EDITING THIS FILE BY HAND IS NOT RECOMMENDED                                 | -->
<!-- =================================================================================== -->
<robot name="AMR_Platform">
  <material name="blue">
    <color rgba="0 0 0.8 1"/>
  </material>
  <material name="black">
    <color rgba="0 0 0 1"/>
  </material>
  <material name="white">
    <color rgba="1 1 1 1"/>
  </material>
  <link name="base_link">
  </link>
  <link name="main_body">
    <visual>
      <origin rpy="1.5707963267949 0 1.5707963267949" xyz="0 0 0"/>
      <geometry>
        <mesh filename="package://amr_visualisation/meshes/AMR_Platform.STL"/>
      </geometry>
      <material name="white"/>
    </visual>
    <collision>
      <origin rpy="1.5707963267949 0 1.5707963267949" xyz="0 0 0"/>
      <geometry>
        <mesh filename="package://amr_visualisation/meshes/AMR_Platform.STL"/>
      </geometry>
    </collision>
    <inertial>
      <mass value="4.07"/>
      <inertia ixx="0.426" ixy="0.0" ixz="0.0" iyy="0.496" iyz="0.0" izz="0.91"/>
    </inertial>
  </link>
  <joint name="main_body_to_base" type="fixed">
    <parent link="base_link"/>
    <child link="main_body"/>
    <origin xyz="0 0 0.085"/>
  </joint>
  <link name="left_wheel">
    <visual>
      <origin rpy="1.5707963267949 0 0" xyz="0 0 0"/>
      <geometry>
        <cylinder length="0.03937" radius="0.088"/>
      </geometry>
      <material name="black"/>
    </visual>
    <collision>
      <geometry>
        <cylinder length="0.03937" radius="0.088"/>
      </geometry>
    </collision>
    <inertial>
      <mass value="0.17"/>
      <inertia ixx="0.000204" ixy="0.0" ixz="0.0" iyy="0.000306" iyz="0.0" izz="0.000204"/>
    </inertial>
  </link>
  <joint name="left_wheel_joint" type="continuous">
    <axis rpy="0 0 0" xyz="0 1 0"/>
    <parent link="main_body"/>
    <child link="left_wheel"/>
    <origin rpy="0 0 0" xyz="0 0.196425 0.000881"/>
  </joint>
  <link name="right_wheel">
    <visual>
      <origin rpy="1.5707963267949 0 0" xyz="0 0 0"/>
      <geometry>
        <cylinder length="0.03937" radius="0.088"/>
      </geometry>
      <material name="black"/>
    </visual>
    <collision>
      <geometry>
        <cylinder length="0.03937" radius="0.088"/>
      </geometry>
    </collision>
    <inertial>
      <mass value="0.17"/>
      <inertia ixx="0.000204" ixy="0.0" ixz="0.0" iyy="0.000306" iyz="0.0" izz="0.000204"/>
    </inertial>
  </link>
  <joint name="right_wheel_joint" type="continuous">
    <axis rpy="0 0 0" xyz="0 1 0"/>
    <parent link="main_body"/>
    <child link="right_wheel"/>
    <origin rpy="3.1415926535897 0 0" xyz="0 -0.196425 0.000881"/>
  </joint>
  <link name="right_front_small_wheel">
    <visual>
      <origin rpy="1.5707963267949 0 0" xyz="0 0 0"/>
      <geometry>
        <cylinder length="0.02775" radius="0.0375"/>
      </geometry>
      <material name="black"/>
    </visual>
    <collision>
      <geometry>
        <cylinder length="0.02775" radius="0.0375"/>
      </geometry>
    </collision>
    <inertial>
      <mass value="0.17"/>
      <inertia ixx="0.000204" ixy="0.0" ixz="0.0" iyy="0.000306" iyz="0.0" izz="0.000204"/>
    </inertial>
  </link>
  <joint name="right_front_small_wheel_joint" type="continuous">
    <axis rpy="0 0 0" xyz="0 1 0"/>
    <parent link="main_body"/>
    <child link="right_front_small_wheel"/>
    <origin rpy="3.1415926535897 0 0" xyz="0.209 -0.108 -0.049"/>
  </joint>
  <link name="left_front_small_wheel">
    <visual>
      <origin rpy="1.5707963267949 0 0" xyz="0 0 0"/>
      <geometry>
        <cylinder length="0.02775" radius="0.0375"/>
      </geometry>
      <material name="black"/>
    </visual>
    <collision>
      <geometry>
        <cylinder length="0.02775" radius="0.0375"/>
      </geometry>
    </collision>
    <inertial>
      <mass value="0.17"/>
      <inertia ixx="0.000204" ixy="0.0" ixz="0.0" iyy="0.000306" iyz="0.0" izz="0.000204"/>
    </inertial>
  </link>
  <joint name="left_front_small_wheel_joint" type="continuous">
    <axis rpy="0 0 0" xyz="0 1 0"/>
    <parent link="main_body"/>
    <child link="left_front_small_wheel"/>
    <origin rpy="0 0 0" xyz="0.209 0.108 -0.049"/>
  </joint>
  <link name="left_back_small_wheel">
    <visual>
      <origin rpy="1.5707963267949 0 0" xyz="0 0 0"/>
      <geometry>
        <cylinder length="0.02775" radius="0.0375"/>
      </geometry>
      <material name="black"/>
    </visual>
    <collision>
      <geometry>
        <cylinder length="0.02775" radius="0.0375"/>
      </geometry>
    </collision>
    <inertial>
      <mass value="0.17"/>
      <inertia ixx="0.000204" ixy="0.0" ixz="0.0" iyy="0.000306" iyz="0.0" izz="0.000204"/>
    </inertial>
  </link>
  <joint name="left_back_small_wheel_joint" type="continuous">
    <axis rpy="0 0 0" xyz="0 1 0"/>
    <parent link="main_body"/>
    <child link="left_back_small_wheel"/>
    <origin rpy="0 0 0" xyz="-0.228 0.156 -0.049"/>
  </joint>
  <link name="right_back_small_wheel">
    <visual>
      <origin rpy="1.5707963267949 0 0" xyz="0 0 0"/>
      <geometry>
        <cylinder length="0.02775" radius="0.0375"/>
      </geometry>
      <material name="black"/>
    </visual>
    <collision>
      <geometry>
        <cylinder length="0.02775" radius="0.0375"/>
      </geometry>
    </collision>
    <inertial>
      <mass value="0.17"/>
      <inertia ixx="0.000204" ixy="0.0" ixz="0.0" iyy="0.000306" iyz="0.0" izz="0.000204"/>
    </inertial>
  </link>
  <joint name="right_back_small_wheel_joint" type="continuous">
    <axis rpy="0 0 0" xyz="0 1 0"/>
    <parent link="main_body"/>
    <child link="right_back_small_wheel"/>
    <origin rpy="3.1415926535897 0 0" xyz="-0.228 -0.156 -0.049"/>
  </joint>

  <joint name="chassis_connector" type="fixed">
    <axis rpy="0 0 1.57" xyz="0 0 0.5"/>
    <parent link="main_body"/>
    <child link="chassis"/>
  </joint>

  <link name="chassis">
    <visual>
      <geometry>
        <mesh filename="package://omron_moma/chassis.obj"/>
      </geometry>
    </visual>
    <collision>
      <geometry>
        <mesh filename="package://omron_moma/chassis.stl"/>
      </geometry>
    </collision>
  </link>

  <joint name="tm_connector" type="fixed">
    <parent link="chassis"/>
    <child link="link_0"/>
    <origin xyz="-0.25 0 0.75" rpy="1.57 0 1.57"/>
  </joint>

  <link name="link_0">
    <visual>
      <geometry>
        <mesh filename="package://tm_models/meshes/tm12_1300/visual/tm12_base.stl"/>
      </geometry>
      <material name="LightGrey">
        <color rgba="0.5 0.5 0.5 1.0"/>
      </material>
    </visual>
    <collision>
      <geometry>
        <mesh filename="package://tm_models/meshes/tm12_1300/collision/tm12_base_c.STL"/>
      </geometry>
    </collision>
    <inertial>
      <mass value="1.0"/>
      <origin rpy="0 0 0" xyz="0 1.57 0"/>
      <inertia ixx="0.00110833289" ixy="0.0" ixz="0.0" iyy="0.0018" iyz="0.0" izz="0.00110833289"/>
    </inertial>
  </link>

  <joint name="joint_1" type="revolute">
    <parent link="link_0"/>
    <child link="link_1"/>
    <origin rpy="0 0 0" xyz="0 0.1652 0"/>
    <axis xyz="0 1 0"/>
    <limit effort="150.0" lower="-4.71238898038469" upper="4.71238898038469" velocity="3.15"/>
    <dynamics damping="0.0" friction="0.0"/>
  </joint>
  
  <link name="link_1">
    <visual>
      <geometry>
        <mesh filename="package://tm_models/meshes/tm12_1300/visual/tm_750w_01.stl"/>
      </geometry>
      <material name="DarkOlive">
        <color rgba="0.3 0.3 0.25 1.0"/>
      </material>
    </visual>
    <collision>
      <geometry>
        <mesh filename="package://tm_models/meshes/tm12_1300/collision/tm_750w_01_c.STL"/>
      </geometry>
    </collision>
    <inertial>
      <mass value="4.5"/>
      <origin rpy="0 0 0" xyz="0 0 0"/>
      <inertia ixx="0.012487495005" ixy="0.0" ixz="0.0" iyy="0.0081" iyz="0.0" izz="0.012487495005"/>
    </inertial>
  </link>

  <joint name="joint_2" type="revolute">
    <parent link="link_1"/>
    <child link="link_2"/>
    <origin rpy="0 0 0" xyz="0 0 0.1801"/>
    <axis xyz="0 0 -1"/>
    <limit effort="150.0" lower="-3.141592653589793" upper="3.141592653589793" velocity="3.15"/>
    <dynamics damping="0.0" friction="0.0"/>
  </joint>

  <link name="link_2">
    <visual>
      <geometry>
        <mesh filename="package://tm_models/meshes/tm12_1300/visual/tm12_arm1.stl"/>
      </geometry>
      <material name="DarkOlive">
        <color rgba="0.3 0.3 0.25 1.0"/>
      </material>
    </visual>
    <collision>
      <geometry>
        <mesh filename="package://tm_models/meshes/tm12_1300/collision/tm12_arm1_c.STL"/>
      </geometry>
    </collision>
    <inertial>
      <mass value="11.0"/>
      <origin rpy="0 0 0" xyz="0 0.31805 0"/>
      <inertia ixx="0.38080445684482295" ixy="0.0" ixz="0.0" iyy="0.019799999999999998" iyz="0.0" izz="0.38080445684482295"/>
    </inertial>
  </link>

  <joint name="joint_3" type="revolute">
    <parent link="link_2"/>
    <child link="link_3"/>
    <origin rpy="0 0 0" xyz="0 0.6361 -0.12980000000000003"/>
    <axis xyz="0 0 -1"/>
    <limit effort="150.0" lower="-3.141592653589793" upper="3.141592653589793" velocity="3.15"/>
    <dynamics damping="0.0" friction="0.0"/>
  </joint>

  <link name="link_3">
    <visual>
      <geometry>
        <mesh filename="package://tm_models/meshes/tm12_1300/visual/tm12_arm2.stl"/>
      </geometry>
      <material name="DarkOlive">
        <color rgba="0.3 0.3 0.25 1.0"/>
      </material>
    </visual>
    <collision>
      <geometry>
        <mesh filename="package://tm_models/meshes/tm12_1300/collision/tm12_arm2_c.STL"/>
      </geometry>
    </collision>
    <inertial>
      <mass value="2.5"/>
      <origin rpy="0 0 0" xyz="0 0.27895 0"/>
      <inertia ixx="0.06610985063938249" ixy="0.0" ixz="0.0" iyy="0.0025312499999999996" iyz="0.0" izz="0.06610985063938249"/>
    </inertial>
  </link>

  <joint name="joint_4" type="revolute">
    <parent link="link_3"/>
    <child link="link_4"/>
    <origin rpy="0 0 0" xyz="0 0.5579 0.106"/>
    <axis xyz="0 0 -1"/>
    <limit effort="150.0" lower="-3.141592653589793" upper="3.141592653589793" velocity="3.15"/>
    <dynamics damping="0.0" friction="0.0"/>
  </joint>

  <link name="link_4">
    <visual>
      <geometry>
        <mesh filename="package://tm_models/meshes/tm12_1300/visual/tm_100w_01.stl"/>
      </geometry>
      <material name="DarkOlive">
        <color rgba="0.3 0.3 0.25 1.0"/>
      </material>
    </visual>
    <collision>
      <geometry>
        <mesh filename="package://tm_models/meshes/tm12_1300/collision/tm_100w_01_c.STL"/>
      </geometry>
    </collision>
    <inertial>
      <mass value="1.45"/>
      <origin rpy="0 0 0" xyz="0 0 0"/>
      <inertia ixx="0.002474061510375" ixy="0.0" ixz="0.0" iyy="0.001468125" iyz="0.0" izz="0.002474061510375"/>
    </inertial>
  </link>

  <joint name="joint_5" type="revolute">
    <parent link="link_4"/>
    <child link="link_5"/>
    <origin rpy="0 0 0" xyz="0 0.106 0"/>
    <axis xyz="0 1 0"/>
    <limit effort="150.0" lower="-3.141592653589793" upper="3.141592653589793" velocity="3.15"/>
    <dynamics damping="0.0" friction="0.0"/>
  </joint>

  <link name="link_5">
    <visual>
      <geometry>
        <mesh filename="package://tm_models/meshes/tm12_1300/visual/tm_100w_02.stl"/>
      </geometry>
      <material name="DarkOlive">
        <color rgba="0.3 0.3 0.25 1.0"/>
      </material>
    </visual>
    <collision>
      <geometry>
        <mesh filename="package://tm_models/meshes/tm12_1300/collision/tm_100w_02_c.stl"/>
      </geometry>
    </collision>
    <inertial>
      <mass value="1.45"/>
      <origin rpy="0 0 0" xyz="0 0 0"/>
      <inertia ixx="0.002474061510375" ixy="0.0" ixz="0.0" iyy="0.002474061510375" iyz="0.0" izz="0.001468125"/>
    </inertial>
  </link>

  <joint name="joint_6" type="revolute">
    <parent link="link_5"/>
    <child link="link_6"/>
    <origin rpy="0 0 0" xyz="0 0 0.11315"/>
    <axis xyz="0 0 1"/>
    <limit effort="150.0" lower="-4.71238898038469" upper="4.71238898038469" velocity="3.15"/>
    <dynamics damping="0.0" friction="0.0"/>
  </joint>

  <link name="link_6">
    <visual>
      <geometry>
        <mesh filename="package://tm_models/meshes/tm12_1300/visual/tm_ee.stl"/>
      </geometry>
      <material name="LightGrey">
        <color rgba="0.5 0.5 0.5 1.0"/>
      </material>
    </visual>
    <collision>
      <geometry>
        <mesh filename="package://tm_models/meshes/tm12_1300/collision/tm_ee_c.stl"/>
      </geometry>
    </collision>
    <inertial>
      <mass value="0.4"/>
      <origin rpy="0 0 0" xyz="0 0 0"/>
      <inertia ixx="0.000322499871" ixy="0.0" ixz="0.0" iyy="0.000322499871" iyz="0.0" izz="0.000405"/>
    </inertial>
  </link>
  
  <joint name="flange_fixed_joint" type="fixed">
    <parent link="link_6"/>
    <child link="flange_link"/>
    <origin rpy="0 0 0" xyz="0 0 0"/>
  </joint>

  <link name="flange_link">
  </link>

  <joint name="joint_EOAT" type="fixed">
    <parent link="flange_link"/>
    <child link="EOAT"/>
    <origin xyz="0 0 0" rpy="0 0 0"/>
    <axis xyz="0 0 0"/>
  </joint>

  <link name="EOAT">
    <visual>
      <geometry>
        <mesh filename="package://tmr_description/meshes/gripper/robotiq/2f-85/robotiq_85_gripper.obj"/>
      </geometry>
    </visual>
    <collision>
      <geometry>
        <mesh filename="package://tmr_description/meshes/gripper/robotiq/2f-85/robotiq_85_gripper.stl"/>
      </geometry>
    </collision>
  </link>
  <!-- ROS base to TM 'base_link' Coordinates transform -->
  <link name="base"/>
  <joint name="base-base_link" type="fixed">
    <parent link="base_link"/>
    <child link="base"/>
    <origin rpy="1.57079 0 0" xyz="0 0 0"/>
    <!-- Note: 0.5 * pi -->
  </joint>
  <!-- Frame coincident with all-zeros TCP on TM controller -->
  <link name="tool0"/>
  <joint name="flange_link-tool0" type="fixed">
    <parent link="flange_link"/>
    <child link="tool0"/>
    <origin rpy="0 0 0" xyz="0 0 0"/>
  </joint>
</robot>
